Workbook

Sheet Summary
A1: Virginia Soda Tax Revenue Estimate | G1: Illustrative Summary Report
A2: Proposed 5.0% Statewide Soda Tax Beginning January 2025
A3: Prepared by: Wataru Hoeltermann | G3: Scenario date: January 1, 2025
A4: 1. Bottom-Line Estimates
A5: Measure | B5: Estimate | D5: Interpretation
A6: Estimated 2025 soda tax revenue | B6: ='Revenue and Consumption'!N10 -> 83996983 | D6: Projected 2025 full-year revenue from a 5% Virginia soda tax, after accounting for the estimated demand response.
A8: No-tax baseline soda consumption | B8: =INT('Revenue and Consumption'!F10) -> 2328279060 | D8: 2024 scaled soda units sold, used as the baseline for 2025 tax scenario
A9: Estimated soda consumption after tax response | B9: =INT('Revenue and Consumption'!K10) -> 2229519348 | D9: Estimated units sold after applying demand response to the baseline
A10: Estimated reduction in consumption | B10: =B8-B9 -> 98759712 | D10: Estimated decline in annual soda units sold relative to the no-tax baseline.
A12: 2. Price Elasticity of Soda Demand by Income Tier | D12: 3. Key Findings
A13: A constant elasticity log-log specification was used: | D13: Finding 1 | F13: Under stated assumptions, the proposed 5% Virginia soda tax is estimated to generate approximately $84.0 million in 2025 revenue.
A14: ln(soda units sold) = α + β ln(soda price per unit)
A15: Where the coefficient β is interpreted as the price elasticity of demand.
A16: Income Tier | B16: Elasticity | D16: Finding 2 | F16: Estimated 2025 soda consumption falls by about 98.8 million units, or roughly by 4.24%, relative to the no-tax baseline.
A17: High ( 100k and above ) | B17: =Elasticity!G7 -> -0.71035913
A18: Medium ( 40k to 100k ) | B18: =Elasticity!G8 -> -0.92885328
A19: Low ( less than 40k ) | B19: =Elasticity!G9 -> -1.9421318 | D19: Finding 3 | F19: Medium-income ZIP stores drive the largest share of revenue and unit reduction because they account for most Virginia soda sales in the sample
A20: Full-sample elasticity estimates were negative across all income tiers, with Low-income ZIP/ZCTA stores showing the strongest price response. In the state-level diagnostic results, High-income stores in Virginia and West Virginia showed positive elasticities of 0.51 and 0.69, respectively. Because positive elasticities are inconsistent with the expected downward-sloping demand relationship and appeared only in narrower state-tier cuts, these results were treated as anomalies and flagged for caution rather than used in the main revenue estimate.
D22: Finding 4 | F22: Estimated price elasticities are negative across income tiers, supporting the use of separate High, Medium, and Low income-tier demand responses.
D26: 4. Key Assumptions
D27: Assumption | F27: Description
D28: 1) Full tax pass-through | F28: Assumes 100% of the tax is reflected in consumer soda prices, increasing consumer soda prices by 5%.
D30: 2) Representative scaling | F30: The 33 Virginia sample stores are treated as representative of 1,000 statewide stores.
D32: 3) Income-tier price elasticities | F32: High, Medium, and Low ZIP/ZCTA price elasticities are applied separately, then summed for the statewide estimate
D35: 4) Price-driven demand response | F35: Revenue is calculated from soda sales after the estimated unit reduction as an expected response to a price increase.
D38: 5) Unit of Analysis | F38: The dataset’s "soda_units_sold" field is treated as the analysis unit provided in the assignment, not as fluid ounces, servings, or containers of a known size. Therefore, the consumption estimate is reported as a change in dataset units sold, not as a fluid-ounce health or volume estimate.
A42: 5. Method in Brief
A43: Step | B43: Description
A44: 1. Complete data inputs | B44: Pulled 2024 ACS 5-year median household income data from the Census API using table "B19013" at ZIP-level. Combined 2022–2024 income data to calculate three-year average income and classify each ZIP/ZCTA into the appropriate income tier.
A45: 2. Build analytical dataset | B45: Used Power Query to reshape the supplied wide monthly sales sheets into a store-month fact table, then linked each record to store, date, state, ZIP/ZCTA income, and income-tier fields for pivoting and slicing.
A46: 3. Explore patterns and anomalies | B46: Reviewed sales, soda units, soda prices, geography, income tiers, and time patterns using PivotTables and charts. I expected higher prices to reduce quantity demanded, but also checked for unstable estimates caused by small store counts or state-tier anomalies.
A47: 4. Estimate demand response | B47: Estimated full-sample soda price elasticity by income tier using a log-log demand specification relating soda units sold to soda price per unit. These elasticity estimates were used as the behavioral response inputs for the tax scenario.
A48: 5. Estimate Virginia tax impact | B48: Used 2024 Virginia soda units and sales as the no-tax baseline, scaled the 33 Virginia sample stores to the assignment assumption of 1,000 stores, applied the proposed 5.0% tax under full pass-through, and calculated post-response tax revenue and the change in soda consumption.

Sheet Time and Place
Q4: Graphs are illustrated from sample set given.
Q5: Takeaways:
Q6: Price per soda is mostly stable, with notable tax-period change to NC due to a large 5% soda tax.
Q9: MD and DC both have a much less demonstrated change, albeit a lower soda tax, they end around the same price per unit as non-taxed states such as VA and WV.
Q22: Takeaways:
Q23: Soda units sold show clear seasonality, with a rise in sales during summer and dip during winter.
Q26: Each state follows a very similar timing, with Georgia consuming approximately 40k more than other states during summertime.
Q29: North Carolina's tax effect is very apparent, with a visible dip in consumption after the tax policy on July, 2023.

Sheet Elasticity and Sales
A4: state | B4: VA
A5: year | B5: 2024
A7: Row Labels | B7: Sum of soda_sales | C7: Sum of soda_sales2
A8: High | B8: 17472271 | C8: 0.30179804
A9: Med | B9: 38908750 | C9: 0.67206976
A10: Low | B10: 1512895.2 | C10: 0.026132197
A11: Grand Total | B11: 57893916 | C11: 1
A15: Income Tier | B15: Elasticity
A16: High | B16: -0.71
A17: Medium | B17: -0.93
A18: Low | B18: -1.94
A35: Low-income ZIP/ZCTA stores show the strongest estimated price response, while High and Medium tiers are less responsive.
A61: Stores in Low-income neighborhoods has the strongest estimated price response, while in High- and Medium-income neighborhoods are less responsive.

Sheet Revenue Estimates & Sensitivity

Sheet Conclusion
A3: 6. Interpretations and Limitations
A4: These estimates should be interpreted as an illustrative fiscal scenario, not as a full causal evaluation of soda tax policy. Under the stated assumptions, the proposed 5% Virginia soda tax is projected to raise revenue while reducing estimated soda units sold. The taxable base remains large enough to generate positive revenue after behavioral adjustment, and the income-tier results suggests that price responsiveness differs across store-area income groups. Actual distributional effects would depend on who bears the tax burden and how the revenue is used thereafter.
A5: Estimate results could differ under alternative scaling methods, different pass-through rates, or store-weighting methods. ZIP/ZCTA-level income tiers represent store information and may not necessarily be capturing household-level tax burden in that area, as people may shop in different zip codes than their home. Elasticity estimates are also based on observed price and quantity patterns, not accounting for random price variation, so it may not reflect product mix, seasonality, store differences, or other omitted factors. This model also does not account for substitution, cross-border shopping, health outcomes, or long-run behaviors.
A7: 7. Further Analysis
A8: Further Analysis | B8: Purpose
A9: Model specification tests | B9: Estimate alternative models with store fixed effects, month/year controls, and income-tier interactions to test whether elasticity estimates are stable.
A10: Geographic detail | B10: Map ZIP/ZCTA-level patterns and test whether results vary by border areas, urban/rural location, or nearby taxed jurisdictions.
A11: Product and unit definition | B11: Clarify if the unit of analysis represents bottles, cases, ounces, or another measurement. We can test whether excise (volume-based) tax estimates differ from price-based.
A12: Substitution and behavior | B12: Examine substitution with other beverages, cross-state shopping, seasonality impacts, long-run behavioral adjustments, and store-level heterogeneity.
A13: Full fiscal impact model | B13: Extend the scenario to include administrative costs, compliance costs, revenue usage, household tax burden, and broader distributional effects.

Sheet Compact tables
A1: Main VA Estimate: 100% Pass-Through Scenario
A2: state | B2: VA
A3: Income | B3: 2024
A5: Income Tier | B5: VA Sample Store Count | C5: Soda Price Per Unit | D5: 2024 Soda Units | E5: 2024 Soda Sales | F5: Scaled Units | G5: Scaled (33 to 1000 stores) 2024 Soda Sales | H5: Soda Price Per Unit | I5: Elasticity | J5: Tax Rate | K5: Est. % Change of Units (log-log proiection) | L5: Estimated Units After Demand Shift | M5: Estimated Unit Change | N5: Sales after Demand Shift | O5: Estimated Tax Revenue | P5: Notes
A6: High | B6: 11 | C6: 0.75451212 | D6: 23124174 | E6: 17472271 | F6: =1000/33*GETPIVOTDATA("[Measures].[Sum of soda_units_sold]",$A$6,"[DimZip].[zip_inc_tier]","[DimZip].[zip_inc_tier].&[High]") -> 7.0073255e+08 | G6: =1000/33*GETPIVOTDATA("[Measures].[Sum of soda_sales]",$A$6,"[DimZip].[zip_inc_tier]","[DimZip].[zip_inc_tier].&[High]") -> 5.2946275e+08 | I6: =Elasticity!G7 -> -0.71035913 | J6: 0.05 | K6: =(1+J6)^I6-1 -> -0.03406481 | L6: =F6*(1+K6) -> 6.7686222e+08 | M6: =L6-F6 -> -23870321 | N6: =G6/F6*L6 -> 5.114267e+08 | O6: =N6*0.05 -> 25571335 | P6: Using VA-only High income tier elasticity produced an elastic (0.51) estimate, but this was only flagged as anomalous and not used for estimations.
A7: Medium | B7: 21 | C7: 0.75284167 | D7: 51721008 | E7: 38908750 | F7: =1000/33*GETPIVOTDATA("[Measures].[Sum of soda_units_sold]",$A$6,"[DimZip].[zip_inc_tier]","[DimZip].[zip_inc_tier].&[Med]") -> 1.5673033e+09 | G7: =1000/33*GETPIVOTDATA("[Measures].[Sum of soda_sales]",$A$6,"[DimZip].[zip_inc_tier]","[DimZip].[zip_inc_tier].&[Med]") -> 1.179053e+09 | I7: =Elasticity!G8 -> -0.92885328 | J7: 0.05 | K7: =(1+J7)^I7-1 -> -0.044307341 | L7: =F7*(1+K7) -> 1.4978602e+09 | M7: =L7-F7 -> -69443041 | N7: =G7/F7*L7 -> 1.1268123e+09 | O7: =N7*0.05 -> 56340617
A8: Low | B8: 1 | C8: 0.761225 | D8: 1988027 | E8: 1512895.2 | F8: =1000/33*GETPIVOTDATA("[Measures].[Sum of soda_units_sold]",$A$6,"[DimZip].[zip_inc_tier]","[DimZip].[zip_inc_tier].&[Low]") -> 60243242 | G8: =1000/33*GETPIVOTDATA("[Measures].[Sum of soda_sales]",$A$6,"[DimZip].[zip_inc_tier]","[DimZip].[zip_inc_tier].&[Low]") -> 45845310 | I8: =Elasticity!G9 -> -1.9421318 | J8: 0.05 | K8: =(1+J8)^I8-1 -> -0.090405995 | L8: =F8*(1+K8) -> 54796892 | M8: =L8-F8 -> -5446350.3 | N8: =G8/F8*L8 -> 41700619 | O8: =N8*0.05 -> 2085031 | P8: Only one VA Low income store was observed, so the upscaled estimate should be treated with caution.
A9: Total | B9: 33 | C9: 0.75365253 | D9: 76833209 | E9: 57893916 | F9: =1000/33*GETPIVOTDATA("[Measures].[Sum of soda_units_sold]",$A$6) -> 2.3282791e+09 | G9: =1000/33*GETPIVOTDATA("[Measures].[Sum of soda_sales]",$A$6) -> 1.7543611e+09 | I9: Tier-summed | J9: 0.05 | K9: =(1+J9)^I9-1 -> #VALUE! | L9: =SUM(L6:L8) -> 2.2295193e+09 | M9: =SUM(M6:M8) -> -98759712 | N9: =SUM(N6:N8) -> 1.6799397e+09 | O9: =SUM(O6:O8) -> 83996983
A10: Notes: Estimated demand response is based on elasticity and the assumed price increase. Tier-level estimates should be treated with caution as sample sizes differ, with the total row being our preferred estimates for revenue and demand effects.
R13: Pass-through sensitivity summary
R14: Pass-through | S14: Consumer Price Increase | T14: Post-Tax Units | U14: Unit Change | V14: Est. Tax Revenue
R15: 1 | S15: 0.05 | T15: 2.2295193e+09 | U15: -98759712 | V15: 83996983
R16: 0.75 | S16: 0.0375 | T16: 2.2533471e+09 | U16: -74931930 | V16: 84894760
R17: 0.5 | S17: 0.025 | T17: 2.2777358e+09 | U17: -50543247 | V17: 85813675
R18: Notes: Consistent trend of lower pass-through produces higher estimated tax revenue, as the smaller consumer price increase leads to a smaller reduction in quantity demanded and thus a larger taxable sales base.
R19: Sensitivity results are illustrative and depend on the assumed pass-through rates.
X21: gt

Sheet Elasticity
A1: Full sample, Constant elasticity (log-log) model for main method.
A2: A constant elasticity log-log model was used because the policy change is percentage-based and the assignment asks for price elasticity by income tier. The log-log specification allows the price coefficient to be interpreted directly as elasticity. This is treated as a transparent workbook-based estimate, not a full causal demand model.
A3: I chose log-log because it aligns the estimation method with the policy scenario: a 5% ad valorem tax creates a percentage price change, and elasticity is a percentage quantity response. More complex models could be tested, but this specification is transparent and appropriate for a short Excel-based assignment.
B5: Income Tier | C5: Obs. count | D5: Store count | E5: Avg soda PPU | F5: Avg monthly units | G5: Elasticity | H5: R-squared | I5: Interpretation
A6: Full Sample | B6: All | C6: =COUNT((dataset[ln_soda_units])) -> 3600 | D6: {=ROWS(_xlfn.UNIQUE(_xlfn._xlws.FILTER(dataset[store_id],(dataset[soda_units_sold]>0)*(dataset[soda_ppu]>0))))} -> 100 | E6: =AVERAGEIFS(dataset[soda_ppu],dataset[soda_units_sold],">0",dataset[soda_ppu],">0") -> 0.72502311 | F6: =AVERAGEIFS(dataset[soda_units_sold],dataset[soda_units_sold],">0",dataset[soda_ppu],">0") -> 203580.39 | G6: =SLOPE(dataset[ln_soda_units],dataset[ln_soda_ppu]) -> -0.97684053 | H6: {=RSQ(_xlfn._xlws.FILTER(dataset[ln_soda_units],(dataset[soda_units_sold]>0)*(dataset[soda_ppu]>0)),_xlfn._xlws.FILTER(dataset[ln_soda_ppu],(dataset[soda_units_sold]>0)*(dataset[soda_ppu]>0)))} -> 0.066619345
B7: High | C7: {=COUNT(_xlfn._xlws.FILTER(dataset[ln_soda_units],dataset[zip_inc_tier]="High",""))} -> 828 | D7: {=ROWS(_xlfn.UNIQUE(_xlfn._xlws.FILTER(dataset[store_id],dataset[zip_inc_tier]="High")))} -> 23 | E7: =AVERAGEIFS(dataset[soda_ppu],dataset[zip_inc_tier],"High") -> 0.72701304 | F7: =AVERAGEIFS(dataset[soda_units_sold],dataset[zip_inc_tier],"High") -> 181586.48 | G7: {=SLOPE( _xlfn._xlws.FILTER(dataset[ln_soda_units],dataset[zip_inc_tier]="High",""), _xlfn._xlws.FILTER(dataset[ln_soda_ppu],dataset[zip_inc_tier]="High","") )} -> -0.71035913 | H7: {=RSQ(_xlfn._xlws.FILTER(dataset[ln_soda_units],dataset[zip_inc_tier]="High"),_xlfn._xlws.FILTER(dataset[ln_soda_ppu],dataset[zip_inc_tier]="High"))} -> 0.024805876 | I7: Assuming 100% pass through, a 1% increase in soda price is associated with an estimated 0.71% decrease in soda units sold.
B8: Medium | C8: {=COUNT(_xlfn._xlws.FILTER(dataset[ln_soda_units],dataset[zip_inc_tier]="Med",""))} -> 2268 | D8: {=ROWS(_xlfn.UNIQUE(_xlfn._xlws.FILTER(dataset[store_id],dataset[zip_inc_tier]="Med")))} -> 63 | E8: =AVERAGEIFS(dataset[soda_ppu],dataset[zip_inc_tier],"Med") -> 0.72360018 | F8: =AVERAGEIFS(dataset[soda_units_sold],dataset[zip_inc_tier],"Med") -> 212169.27 | G8: {=SLOPE( _xlfn._xlws.FILTER(dataset[ln_soda_units],dataset[zip_inc_tier]="Med",""), _xlfn._xlws.FILTER(dataset[ln_soda_ppu],dataset[zip_inc_tier]="Med","") )} -> -0.92885328 | H8: {=RSQ(_xlfn._xlws.FILTER(dataset[ln_soda_units],dataset[zip_inc_tier]="Med"),_xlfn._xlws.FILTER(dataset[ln_soda_ppu],dataset[zip_inc_tier]="Med"))} -> 0.08081638 | I8: Assuming 100% pass through, a 1% increase in soda price is associated with an estimated 0.93% decrease in soda units sold.
B9: Low | C9: {=COUNT(_xlfn._xlws.FILTER(dataset[ln_soda_units],dataset[zip_inc_tier]="Low",""))} -> 180 | D9: {=ROWS(_xlfn.UNIQUE(_xlfn._xlws.FILTER(dataset[store_id],dataset[zip_inc_tier]="Low")))} -> 5 | E9: =AVERAGEIFS(dataset[soda_ppu],dataset[zip_inc_tier],"Low") -> 0.73157556 | F9: =AVERAGEIFS(dataset[soda_units_sold],dataset[zip_inc_tier],"Low") -> 194329.01 | G9: {=SLOPE( _xlfn._xlws.FILTER(dataset[ln_soda_units],dataset[zip_inc_tier]="Low",""), _xlfn._xlws.FILTER(dataset[ln_soda_ppu],dataset[zip_inc_tier]="Low","") )} -> -1.9421318 | H9: {=RSQ(_xlfn._xlws.FILTER(dataset[ln_soda_units],dataset[zip_inc_tier]="Low"),_xlfn._xlws.FILTER(dataset[ln_soda_ppu],dataset[zip_inc_tier]="Low"))} -> 0.2421674 | I9: Assuming 100% pass through, a 1% increase in soda price is associated with an estimated 1.94% decrease in soda units sold.
A10: Subsamples:
A11: VA only | B11: All | C11: {=COUNT(_xlfn._xlws.FILTER(dataset[ln_soda_units],dataset[state]="VA",""))} -> 1188 | D11: {=ROWS(_xlfn.UNIQUE(_xlfn._xlws.FILTER(dataset[store_id],(dataset[state]="VA")*(dataset[soda_units_sold]>0)*(dataset[soda_ppu]>0))))} -> 33 | E11: =AVERAGEIFS(dataset[soda_ppu],dataset[state],"VA",dataset[soda_units_sold],">0",dataset[soda_ppu],">0") -> 0.72935589 | F11: =AVERAGEIFS(dataset[soda_units_sold],dataset[state],"VA",dataset[soda_units_sold],">0",dataset[soda_ppu],">0") -> 196974.36 | G11: {=SLOPE(_xlfn._xlws.FILTER(dataset[ln_soda_units],dataset[state]="VA",""),_xlfn._xlws.FILTER(dataset[ln_soda_ppu],dataset[state]="VA",""))} -> -0.34704711 | H11: {=RSQ(_xlfn._xlws.FILTER(dataset[ln_soda_units],(dataset[state]="VA")*(dataset[soda_units_sold]>0)*(dataset[soda_ppu]>0)),_xlfn._xlws.FILTER(dataset[ln_soda_ppu],(dataset[state]="VA")*(dataset[soda_units_sold]>0)*(dataset[soda_ppu]>0)))} -> 0.0046073872 | I11: Very little sensitivity check, but very low r-squared suggests that price alone explains little of the variation in Virginia's soda units with respect to price.
B12: High | C12: {=COUNT(_xlfn._xlws.FILTER(dataset[ln_soda_units],(dataset[zip_inc_tier]="High")*(dataset[state]="VA"),""))} -> 396 | D12: {=ROWS(_xlfn.UNIQUE(_xlfn._xlws.FILTER(dataset[store_id],(dataset[zip_inc_tier]="High")*(dataset[state]="VA"))))} -> 11 | E12: =AVERAGEIFS(dataset[soda_ppu],dataset[zip_inc_tier],"High",dataset[state],"VA") -> 0.73048005 | F12: =AVERAGEIFS(dataset[soda_units_sold],dataset[zip_inc_tier],"High",dataset[state],"VA") -> 177787.49 | G12: {=SLOPE( _xlfn._xlws.FILTER(dataset[ln_soda_units],(dataset[zip_inc_tier]="High")*(dataset[state]="VA"),""), _xlfn._xlws.FILTER(dataset[ln_soda_ppu],(dataset[zip_inc_tier]="High")*(dataset[state]="VA"),"") )} -> 0.5059806 | H12: {=RSQ(_xlfn._xlws.FILTER(dataset[ln_soda_units],(dataset[zip_inc_tier]="High")*(dataset[state]="VA")),_xlfn._xlws.FILTER(dataset[ln_soda_ppu],(dataset[zip_inc_tier]="High")*(dataset[state]="VA")))} -> 0.0094590573 | I12: The positive elasticity should be treated as a data anomaly and not interpreted that higher prices increase soda demand.
B13: Medium | C13: {=COUNT(_xlfn._xlws.FILTER(dataset[ln_soda_units],(dataset[zip_inc_tier]="Med")*(dataset[state]="VA"),""))} -> 756 | D13: {=ROWS(_xlfn.UNIQUE(_xlfn._xlws.FILTER(dataset[store_id],(dataset[zip_inc_tier]="Med")*(dataset[state]="VA"))))} -> 21 | E13: =AVERAGEIFS(dataset[soda_ppu],dataset[zip_inc_tier],"Med",dataset[state],"VA") -> 0.72851071 | F13: =AVERAGEIFS(dataset[soda_units_sold],dataset[zip_inc_tier],"Med",dataset[state],"VA") -> 208286.47 | G13: {=SLOPE( _xlfn._xlws.FILTER(dataset[ln_soda_units],(dataset[zip_inc_tier]="Med")*(dataset[state]="VA"),""), _xlfn._xlws.FILTER(dataset[ln_soda_ppu],(dataset[zip_inc_tier]="Med")*(dataset[state]="VA"),"") )} -> -0.78466403 | H13: {=RSQ(_xlfn._xlws.FILTER(dataset[ln_soda_units],(dataset[zip_inc_tier]="Med")*(dataset[state]="VA")),_xlfn._xlws.FILTER(dataset[ln_soda_ppu],(dataset[zip_inc_tier]="Med")*(dataset[state]="VA")))} -> 0.031851899 | I13: Assuming 100% pass through, a 1% increase in soda price is associated with an estimated 0.78% decrease in soda units sold.
B14: Low | C14: {=COUNT(_xlfn._xlws.FILTER(dataset[ln_soda_units],(dataset[zip_inc_tier]="Low")*(dataset[state]="VA"),""))} -> 36 | D14: {=ROWS(_xlfn.UNIQUE(_xlfn._xlws.FILTER(dataset[store_id],(dataset[zip_inc_tier]="Low")*(dataset[state]="VA"))))} -> 1 | E14: =AVERAGEIFS(dataset[soda_ppu],dataset[zip_inc_tier],"Low",dataset[state],"VA") -> 0.73473889 | F14: =AVERAGEIFS(dataset[soda_units_sold],dataset[zip_inc_tier],"Low",dataset[state],"VA") -> 170475.61 | G14: {=SLOPE( _xlfn._xlws.FILTER(dataset[ln_soda_units],(dataset[zip_inc_tier]="Low")*(dataset[state]="VA"),""), _xlfn._xlws.FILTER(dataset[ln_soda_ppu],(dataset[zip_inc_tier]="Low")*(dataset[state]="VA"),"") )} -> -1.0151468 | H14: {=RSQ(_xlfn._xlws.FILTER(dataset[ln_soda_units],(dataset[zip_inc_tier]="Low")*(dataset[state]="VA")),_xlfn._xlws.FILTER(dataset[ln_soda_ppu],(dataset[zip_inc_tier]="Low")*(dataset[state]="VA")))} -> 0.031076426 | I14: Assuming 100% pass through, a 1% increase in soda price is associated with an estimated 1.02% decrease in soda units sold.
A16: DC | B16: All | C16: {=COUNT(_xlfn._xlws.FILTER(dataset[ln_soda_units],dataset[state]="DC",""))} -> 72 | D16: {=ROWS(_xlfn.UNIQUE(_xlfn._xlws.FILTER(dataset[store_id],(dataset[state]="DC")*(dataset[soda_units_sold]>0)*(dataset[soda_ppu]>0))))} -> 2 | E16: =AVERAGEIFS(dataset[soda_ppu],dataset[state],"DC",dataset[soda_units_sold],">0",dataset[soda_ppu],">0") -> 0.72162917 | F16: =AVERAGEIFS(dataset[soda_units_sold],dataset[state],"DC",dataset[soda_units_sold],">0",dataset[soda_ppu],">0") -> 204413.64 | G16: {=SLOPE(_xlfn._xlws.FILTER(dataset[ln_soda_units],dataset[state]="DC",""),_xlfn._xlws.FILTER(dataset[ln_soda_ppu],dataset[state]="DC",""))} -> -0.4049745 | H16: {=RSQ(_xlfn._xlws.FILTER(dataset[ln_soda_units],(dataset[state]="DC")*(dataset[soda_units_sold]>0)*(dataset[soda_ppu]>0)),_xlfn._xlws.FILTER(dataset[ln_soda_ppu],(dataset[state]="DC")*(dataset[soda_units_sold]>0)*(dataset[soda_ppu]>0)))} -> 0.0058344604 | I16: Existing 2% tax every year
B17: High | C17: {=COUNT(_xlfn._xlws.FILTER(dataset[ln_soda_units],(dataset[zip_inc_tier]="High")*(dataset[state]="DC"),""))} -> 36 | D17: {=ROWS(_xlfn.UNIQUE(_xlfn._xlws.FILTER(dataset[store_id],(dataset[zip_inc_tier]="High")*(dataset[state]="DC"))))} -> 1 | E17: =AVERAGEIFS(dataset[soda_ppu],dataset[zip_inc_tier],"High",dataset[state],"DC") -> 0.72408889 | F17: =AVERAGEIFS(dataset[soda_units_sold],dataset[zip_inc_tier],"High",dataset[state],"DC") -> 204131.31 | G17: {=SLOPE( _xlfn._xlws.FILTER(dataset[ln_soda_units],(dataset[zip_inc_tier]="High")*(dataset[state]="DC"),""), _xlfn._xlws.FILTER(dataset[ln_soda_ppu],(dataset[zip_inc_tier]="High")*(dataset[state]="DC"),"") )} -> -0.22237294 | H17: {=RSQ(_xlfn._xlws.FILTER(dataset[ln_soda_units],(dataset[zip_inc_tier]="High")*(dataset[state]="DC")),_xlfn._xlws.FILTER(dataset[ln_soda_ppu],(dataset[zip_inc_tier]="High")*(dataset[state]="DC")))} -> 0.0015577963
B18: Medium | C18: {=COUNT(_xlfn._xlws.FILTER(dataset[ln_soda_units],(dataset[zip_inc_tier]="Med")*(dataset[state]="DC"),""))} -> 0 | I18: No sample observations in this income tier for this state.
B19: Low | C19: {=COUNT(_xlfn._xlws.FILTER(dataset[ln_soda_units],(dataset[zip_inc_tier]="Low")*(dataset[state]="DC"),""))} -> 0 | I19: No sample observations in this income tier for this state.
A20: MD | B20: All | C20: {=COUNT(_xlfn._xlws.FILTER(dataset[ln_soda_units],dataset[state]="MD",""))} -> 540 | D20: {=ROWS(_xlfn.UNIQUE(_xlfn._xlws.FILTER(dataset[store_id],(dataset[state]="MD")*(dataset[soda_units_sold]>0)*(dataset[soda_ppu]>0))))} -> 15 | E20: =AVERAGEIFS(dataset[soda_ppu],dataset[state],"MD",dataset[soda_units_sold],">0",dataset[soda_ppu],">0") -> 0.73191185 | F20: =AVERAGEIFS(dataset[soda_units_sold],dataset[state],"MD",dataset[soda_units_sold],">0",dataset[soda_ppu],">0") -> 192794.26 | G20: {=SLOPE(_xlfn._xlws.FILTER(dataset[ln_soda_units],dataset[state]="MD",""),_xlfn._xlws.FILTER(dataset[ln_soda_ppu],dataset[state]="MD",""))} -> -1.4393072 | H20: {=RSQ(_xlfn._xlws.FILTER(dataset[ln_soda_units],(dataset[state]="MD")*(dataset[soda_units_sold]>0)*(dataset[soda_ppu]>0)),_xlfn._xlws.FILTER(dataset[ln_soda_ppu],(dataset[state]="MD")*(dataset[soda_units_sold]>0)*(dataset[soda_ppu]>0)))} -> 0.085184499 | I20: 1% tax starting in January 2023 and increased it to 2% in January of 2024
B21: High | C21: {=COUNT(_xlfn._xlws.FILTER(dataset[ln_soda_units],(dataset[zip_inc_tier]="High")*(dataset[state]="MD"),""))} -> 252 | D21: {=ROWS(_xlfn.UNIQUE(_xlfn._xlws.FILTER(dataset[store_id],(dataset[zip_inc_tier]="High")*(dataset[state]="MD"))))} -> 7 | E21: =AVERAGEIFS(dataset[soda_ppu],dataset[zip_inc_tier],"High",dataset[state],"MD") -> 0.73967302 | F21: =AVERAGEIFS(dataset[soda_units_sold],dataset[zip_inc_tier],"High",dataset[state],"MD") -> 174528.21 | G21: {=SLOPE( _xlfn._xlws.FILTER(dataset[ln_soda_units],(dataset[zip_inc_tier]="High")*(dataset[state]="MD"),""), _xlfn._xlws.FILTER(dataset[ln_soda_ppu],(dataset[zip_inc_tier]="High")*(dataset[state]="MD"),"") )} -> -1.4528595 | H21: {=RSQ(_xlfn._xlws.FILTER(dataset[ln_soda_units],(dataset[zip_inc_tier]="High")*(dataset[state]="MD")),_xlfn._xlws.FILTER(dataset[ln_soda_ppu],(dataset[zip_inc_tier]="High")*(dataset[state]="MD")))} -> 0.079733121
B22: Medium | C22: {=COUNT(_xlfn._xlws.FILTER(dataset[ln_soda_units],(dataset[zip_inc_tier]="Med")*(dataset[state]="MD"),""))} -> 288 | D22: {=ROWS(_xlfn.UNIQUE(_xlfn._xlws.FILTER(dataset[store_id],(dataset[zip_inc_tier]="Med")*(dataset[state]="MD"))))} -> 8 | E22: =AVERAGEIFS(dataset[soda_ppu],dataset[zip_inc_tier],"Med",dataset[state],"MD") -> 0.72512083 | F22: =AVERAGEIFS(dataset[soda_units_sold],dataset[zip_inc_tier],"Med",dataset[state],"MD") -> 208777.05 | G22: {=SLOPE( _xlfn._xlws.FILTER(dataset[ln_soda_units],(dataset[zip_inc_tier]="Med")*(dataset[state]="MD"),""), _xlfn._xlws.FILTER(dataset[ln_soda_ppu],(dataset[zip_inc_tier]="Med")*(dataset[state]="MD"),"") )} -> -0.69447111 | H22: {=RSQ(_xlfn._xlws.FILTER(dataset[ln_soda_units],(dataset[zip_inc_tier]="Med")*(dataset[state]="MD")),_xlfn._xlws.FILTER(dataset[ln_soda_ppu],(dataset[zip_inc_tier]="Med")*(dataset[state]="MD")))} -> 0.03054278
B23: Low | C23: {=COUNT(_xlfn._xlws.FILTER(dataset[ln_soda_units],(dataset[zip_inc_tier]="Low")*(dataset[state]="MD"),""))} -> 0 | I23: No sample observations in this income tier for this state.
A24: NC | B24: All | C24: {=COUNT(_xlfn._xlws.FILTER(dataset[ln_soda_units],dataset[state]="NC",""))} -> 684 | D24: {=ROWS(_xlfn.UNIQUE(_xlfn._xlws.FILTER(dataset[store_id],(dataset[state]="NC")*(dataset[soda_units_sold]>0)*(dataset[soda_ppu]>0))))} -> 19 | E24: =AVERAGEIFS(dataset[soda_ppu],dataset[state],"NC",dataset[soda_units_sold],">0",dataset[soda_ppu],">0") -> 0.75083143 | F24: =AVERAGEIFS(dataset[soda_units_sold],dataset[state],"NC",dataset[soda_units_sold],">0",dataset[soda_ppu],">0") -> 203433.56 | G24: {=SLOPE(_xlfn._xlws.FILTER(dataset[ln_soda_units],dataset[state]="NC",""),_xlfn._xlws.FILTER(dataset[ln_soda_ppu],dataset[state]="NC",""))} -> -0.92154405 | H24: {=RSQ(_xlfn._xlws.FILTER(dataset[ln_soda_units],(dataset[state]="NC")*(dataset[soda_units_sold]>0)*(dataset[soda_ppu]>0)),_xlfn._xlws.FILTER(dataset[ln_soda_ppu],(dataset[state]="NC")*(dataset[soda_units_sold]>0)*(dataset[soda_ppu]>0)))} -> 0.075439791 | I24: 5% tax starting July 2023
B25: High | C25: {=COUNT(_xlfn._xlws.FILTER(dataset[ln_soda_units],(dataset[zip_inc_tier]="High")*(dataset[state]="NC"),""))} -> 0 | I25: No sample observations in this income tier for this state.
B26: Medium | C26: {=COUNT(_xlfn._xlws.FILTER(dataset[ln_soda_units],(dataset[zip_inc_tier]="Med")*(dataset[state]="NC"),""))} -> 504 | D26: {=ROWS(_xlfn.UNIQUE(_xlfn._xlws.FILTER(dataset[store_id],(dataset[zip_inc_tier]="Med")*(dataset[state]="NC"))))} -> 14 | E26: =AVERAGEIFS(dataset[soda_ppu],dataset[zip_inc_tier],"Med",dataset[state],"NC") -> 0.7544502 | F26: =AVERAGEIFS(dataset[soda_units_sold],dataset[zip_inc_tier],"Med",dataset[state],"NC") -> 203516.74 | G26: {=SLOPE( _xlfn._xlws.FILTER(dataset[ln_soda_units],(dataset[zip_inc_tier]="Med")*(dataset[state]="NC"),""), _xlfn._xlws.FILTER(dataset[ln_soda_ppu],(dataset[zip_inc_tier]="Med")*(dataset[state]="NC"),"") )} -> -0.81394402 | H26: {=RSQ(_xlfn._xlws.FILTER(dataset[ln_soda_units],(dataset[zip_inc_tier]="Med")*(dataset[state]="NC")),_xlfn._xlws.FILTER(dataset[ln_soda_ppu],(dataset[zip_inc_tier]="Med")*(dataset[state]="NC")))} -> 0.058742898
B27: Low | C27: {=COUNT(_xlfn._xlws.FILTER(dataset[ln_soda_units],(dataset[zip_inc_tier]="Low")*(dataset[state]="NC"),""))} -> 72 | D27: {=ROWS(_xlfn.UNIQUE(_xlfn._xlws.FILTER(dataset[store_id],(dataset[zip_inc_tier]="Low")*(dataset[state]="NC"))))} -> 2 | E27: =AVERAGEIFS(dataset[soda_ppu],dataset[zip_inc_tier],"Low",dataset[state],"NC") -> 0.75161389 | F27: =AVERAGEIFS(dataset[soda_units_sold],dataset[zip_inc_tier],"Low",dataset[state],"NC") -> 193479.46 | G27: {=SLOPE( _xlfn._xlws.FILTER(dataset[ln_soda_units],(dataset[zip_inc_tier]="Low")*(dataset[state]="NC"),""), _xlfn._xlws.FILTER(dataset[ln_soda_ppu],(dataset[zip_inc_tier]="Low")*(dataset[state]="NC"),"") )} -> -1.5619225 | H27: {=RSQ(_xlfn._xlws.FILTER(dataset[ln_soda_units],(dataset[zip_inc_tier]="Low")*(dataset[state]="NC")),_xlfn._xlws.FILTER(dataset[ln_soda_ppu],(dataset[zip_inc_tier]="Low")*(dataset[state]="NC")))} -> 0.22024515
A28: WV | B28: All | C28: {=COUNT(_xlfn._xlws.FILTER(dataset[ln_soda_units],dataset[state]="WV",""))} -> 468 | D28: {=ROWS(_xlfn.UNIQUE(_xlfn._xlws.FILTER(dataset[store_id],(dataset[state]="WV")*(dataset[soda_units_sold]>0)*(dataset[soda_ppu]>0))))} -> 13 | E28: =AVERAGEIFS(dataset[soda_ppu],dataset[state],"WV",dataset[soda_units_sold],">0",dataset[soda_ppu],">0") -> 0.73142308 | F28: =AVERAGEIFS(dataset[soda_units_sold],dataset[state],"WV",dataset[soda_units_sold],">0",dataset[soda_ppu],">0") -> 203054.45 | G28: {=SLOPE(_xlfn._xlws.FILTER(dataset[ln_soda_units],dataset[state]="WV",""),_xlfn._xlws.FILTER(dataset[ln_soda_ppu],dataset[state]="WV",""))} -> -1.0495232 | H28: {=RSQ(_xlfn._xlws.FILTER(dataset[ln_soda_units],(dataset[state]="WV")*(dataset[soda_units_sold]>0)*(dataset[soda_ppu]>0)),_xlfn._xlws.FILTER(dataset[ln_soda_ppu],(dataset[state]="WV")*(dataset[soda_units_sold]>0)*(dataset[soda_ppu]>0)))} -> 0.068141226 | I28: Neighboring State
B29: High | C29: {=COUNT(_xlfn._xlws.FILTER(dataset[ln_soda_units],(dataset[zip_inc_tier]="High")*(dataset[state]="WV"),""))} -> 36 | D29: {=ROWS(_xlfn.UNIQUE(_xlfn._xlws.FILTER(dataset[store_id],(dataset[zip_inc_tier]="High")*(dataset[state]="WV"))))} -> 1 | E29: =AVERAGEIFS(dataset[soda_ppu],dataset[zip_inc_tier],"High",dataset[state],"WV") -> 0.75346389 | F29: =AVERAGEIFS(dataset[soda_units_sold],dataset[zip_inc_tier],"High",dataset[state],"WV") -> 184153.19 | G29: {=SLOPE( _xlfn._xlws.FILTER(dataset[ln_soda_units],(dataset[zip_inc_tier]="High")*(dataset[state]="WV"),""), _xlfn._xlws.FILTER(dataset[ln_soda_ppu],(dataset[zip_inc_tier]="High")*(dataset[state]="WV"),"") )} -> 0.68975056 | H29: {=RSQ(_xlfn._xlws.FILTER(dataset[ln_soda_units],(dataset[zip_inc_tier]="High")*(dataset[state]="WV")),_xlfn._xlws.FILTER(dataset[ln_soda_ppu],(dataset[zip_inc_tier]="High")*(dataset[state]="WV")))} -> 0.018933474 | I29: The only other High-income anomaly is in WV
B30: Medium | C30: {=COUNT(_xlfn._xlws.FILTER(dataset[ln_soda_units],(dataset[zip_inc_tier]="Med")*(dataset[state]="WV"),""))} -> 288 | D30: {=ROWS(_xlfn.UNIQUE(_xlfn._xlws.FILTER(dataset[store_id],(dataset[zip_inc_tier]="Med")*(dataset[state]="WV"))))} -> 8 | E30: =AVERAGEIFS(dataset[soda_ppu],dataset[zip_inc_tier],"Med",dataset[state],"WV") -> 0.71975104 | F30: =AVERAGEIFS(dataset[soda_units_sold],dataset[zip_inc_tier],"Med",dataset[state],"WV") -> 212701.03 | G30: {=SLOPE( _xlfn._xlws.FILTER(dataset[ln_soda_units],(dataset[zip_inc_tier]="Med")*(dataset[state]="WV"),""), _xlfn._xlws.FILTER(dataset[ln_soda_ppu],(dataset[zip_inc_tier]="Med")*(dataset[state]="WV"),"") )} -> -0.7019305 | H30: {=RSQ(_xlfn._xlws.FILTER(dataset[ln_soda_units],(dataset[zip_inc_tier]="Med")*(dataset[state]="WV")),_xlfn._xlws.FILTER(dataset[ln_soda_ppu],(dataset[zip_inc_tier]="Med")*(dataset[state]="WV")))} -> 0.034710873
B31: Low | C31: {=COUNT(_xlfn._xlws.FILTER(dataset[ln_soda_units],(dataset[zip_inc_tier]="Low")*(dataset[state]="WV"),""))} -> 36 | D31: {=ROWS(_xlfn.UNIQUE(_xlfn._xlws.FILTER(dataset[store_id],(dataset[zip_inc_tier]="Low")*(dataset[state]="WV"))))} -> 1 | E31: =AVERAGEIFS(dataset[soda_ppu],dataset[zip_inc_tier],"Low",dataset[state],"WV") -> 0.73891111 | F31: =AVERAGEIFS(dataset[soda_units_sold],dataset[zip_inc_tier],"Low",dataset[state],"WV") -> 172414.17 | G31: {=SLOPE( _xlfn._xlws.FILTER(dataset[ln_soda_units],(dataset[zip_inc_tier]="Low")*(dataset[state]="WV"),""), _xlfn._xlws.FILTER(dataset[ln_soda_ppu],(dataset[zip_inc_tier]="Low")*(dataset[state]="WV"),"") )} -> -1.2768575 | H31: {=RSQ(_xlfn._xlws.FILTER(dataset[ln_soda_units],(dataset[zip_inc_tier]="Low")*(dataset[state]="WV")),_xlfn._xlws.FILTER(dataset[ln_soda_ppu],(dataset[zip_inc_tier]="Low")*(dataset[state]="WV")))} -> 0.04364113
A32: GA | B32: All | C32: {=COUNT(_xlfn._xlws.FILTER(dataset[ln_soda_units],dataset[state]="GA",""))} -> 648 | D32: {=ROWS(_xlfn.UNIQUE(_xlfn._xlws.FILTER(dataset[store_id],(dataset[state]="GA")*(dataset[soda_units_sold]>0)*(dataset[soda_ppu]>0))))} -> 18 | E32: =AVERAGEIFS(dataset[soda_ppu],dataset[state],"GA",dataset[soda_units_sold],">0",dataset[soda_ppu],">0") -> 0.67985185 | F32: =AVERAGEIFS(dataset[soda_units_sold],dataset[state],"GA",dataset[soda_units_sold],">0",dataset[soda_ppu],">0") -> 225122.13 | G32: {=SLOPE(_xlfn._xlws.FILTER(dataset[ln_soda_units],dataset[state]="GA",""),_xlfn._xlws.FILTER(dataset[ln_soda_ppu],dataset[state]="GA",""))} -> -0.6339563 | H32: {=RSQ(_xlfn._xlws.FILTER(dataset[ln_soda_units],(dataset[state]="GA")*(dataset[soda_units_sold]>0)*(dataset[soda_ppu]>0)),_xlfn._xlws.FILTER(dataset[ln_soda_ppu],(dataset[state]="GA")*(dataset[soda_units_sold]>0)*(dataset[soda_ppu]>0)))} -> 0.021398984 | I32: Neighboring State
B33: High | C33: {=COUNT(_xlfn._xlws.FILTER(dataset[ln_soda_units],(dataset[zip_inc_tier]="High")*(dataset[state]="GA"),""))} -> 108 | D33: {=ROWS(_xlfn.UNIQUE(_xlfn._xlws.FILTER(dataset[store_id],(dataset[zip_inc_tier]="High")*(dataset[state]="GA"))))} -> 3 | E33: =AVERAGEIFS(dataset[soda_ppu],dataset[zip_inc_tier],"High",dataset[state],"GA") -> 0.67691852 | F33: =AVERAGEIFS(dataset[soda_units_sold],dataset[zip_inc_tier],"High",dataset[state],"GA") -> 203614.9 | G33: {=SLOPE( _xlfn._xlws.FILTER(dataset[ln_soda_units],(dataset[zip_inc_tier]="High")*(dataset[state]="GA"),""), _xlfn._xlws.FILTER(dataset[ln_soda_ppu],(dataset[zip_inc_tier]="High")*(dataset[state]="GA"),"") )} -> -0.66169378 | H33: {=RSQ(_xlfn._xlws.FILTER(dataset[ln_soda_units],(dataset[zip_inc_tier]="High")*(dataset[state]="GA")),_xlfn._xlws.FILTER(dataset[ln_soda_ppu],(dataset[zip_inc_tier]="High")*(dataset[state]="GA")))} -> 0.019079092
B34: Medium | C34: {=COUNT(_xlfn._xlws.FILTER(dataset[ln_soda_units],(dataset[zip_inc_tier]="Med")*(dataset[state]="GA"),""))} -> 432 | D34: {=ROWS(_xlfn.UNIQUE(_xlfn._xlws.FILTER(dataset[store_id],(dataset[zip_inc_tier]="Med")*(dataset[state]="GA"))))} -> 12 | E34: =AVERAGEIFS(dataset[soda_ppu],dataset[zip_inc_tier],"Med",dataset[state],"GA") -> 0.68056736 | F34: =AVERAGEIFS(dataset[soda_units_sold],dataset[zip_inc_tier],"Med",dataset[state],"GA") -> 230965.78 | G34: {=SLOPE( _xlfn._xlws.FILTER(dataset[ln_soda_units],(dataset[zip_inc_tier]="Med")*(dataset[state]="GA"),""), _xlfn._xlws.FILTER(dataset[ln_soda_ppu],(dataset[zip_inc_tier]="Med")*(dataset[state]="GA"),"") )} -> -0.65710754 | H34: {=RSQ(_xlfn._xlws.FILTER(dataset[ln_soda_units],(dataset[zip_inc_tier]="Med")*(dataset[state]="GA")),_xlfn._xlws.FILTER(dataset[ln_soda_ppu],(dataset[zip_inc_tier]="Med")*(dataset[state]="GA")))} -> 0.027287226
B35: Low | C35: {=COUNT(_xlfn._xlws.FILTER(dataset[ln_soda_units],(dataset[zip_inc_tier]="Low")*(dataset[state]="GA"),""))} -> 36 | D35: {=ROWS(_xlfn.UNIQUE(_xlfn._xlws.FILTER(dataset[store_id],(dataset[zip_inc_tier]="Low")*(dataset[state]="GA"))))} -> 1 | E35: =AVERAGEIFS(dataset[soda_ppu],dataset[zip_inc_tier],"Low",dataset[state],"GA") -> 0.681 | F35: =AVERAGEIFS(dataset[soda_units_sold],dataset[zip_inc_tier],"Low",dataset[state],"GA") -> 241796.33 | G35: {=SLOPE( _xlfn._xlws.FILTER(dataset[ln_soda_units],(dataset[zip_inc_tier]="Low")*(dataset[state]="GA"),""), _xlfn._xlws.FILTER(dataset[ln_soda_ppu],(dataset[zip_inc_tier]="Low")*(dataset[state]="GA"),"") )} -> -0.61684725 | H35: {=RSQ(_xlfn._xlws.FILTER(dataset[ln_soda_units],(dataset[zip_inc_tier]="Low")*(dataset[state]="GA")),_xlfn._xlws.FILTER(dataset[ln_soda_ppu],(dataset[zip_inc_tier]="Low")*(dataset[state]="GA")))} -> 0.0096546116
A36: *Full Sample includes elasticity from zip codes with no median income data available.
A38: Income Tier | B38: 2022 Avg PPU | C38: 2022 Avg Units | D38: 2024 Avg PPU | E38: 2024 Avg Units | F38: Midpoint Elasticity | G38: Note
A39: All | B39: =IFERROR(AVERAGEIFS(dataset[soda_ppu],dataset[zip_inc_tier],"High",dataset[year_month],">=202201",dataset[year_month],"<=202212",dataset[soda_ppu],">0",dataset[soda_units_sold],">0"),"No rows") -> 0.70590181 | C39: =IFERROR(AVERAGEIFS(dataset[soda_units_sold],dataset[year_month],">=202201",dataset[year_month],"<=202212",dataset[soda_ppu],">0",dataset[soda_units_sold],">0"),"No rows") -> 207267.44 | D39: =IFERROR(AVERAGEIFS(dataset[soda_ppu],dataset[year_month],">=202401",dataset[year_month],"<=202412",dataset[soda_ppu],">0",dataset[soda_units_sold],">0"),"No rows") -> 0.75325942 | E39: =IFERROR(AVERAGEIFS(dataset[soda_units_sold],dataset[year_month],">=202401",dataset[year_month],"<=202412",dataset[soda_ppu],">0",dataset[soda_units_sold],">0"),"No rows") -> 199263.95 | F39: =((E39-C39)/AVERAGE(C39,E39))/((D39-B39)/AVERAGE(B39,D39)) -> -0.60659501
A40: High | B40: =IFERROR(AVERAGEIFS(dataset[soda_ppu],dataset[zip_inc_tier],"High",dataset[year_month],">=202201",dataset[year_month],"<=202212",dataset[soda_ppu],">0",dataset[soda_units_sold],">0"),"No rows") -> 0.70590181 | C40: =IFERROR(AVERAGEIFS(dataset[soda_units_sold],dataset[zip_inc_tier],A40,dataset[year_month],">=202201",dataset[year_month],"<=202212",dataset[soda_ppu],">0",dataset[soda_units_sold],">0"),"No rows") -> 183807.1 | D40: =IFERROR(AVERAGEIFS(dataset[soda_ppu],dataset[zip_inc_tier],A40,dataset[year_month],">=202401",dataset[year_month],"<=202412",dataset[soda_ppu],">0",dataset[soda_units_sold],">0"),"No rows") -> 0.75279493 | E40: =IFERROR(AVERAGEIFS(dataset[soda_units_sold],dataset[zip_inc_tier],A40,dataset[year_month],">=202401",dataset[year_month],"<=202412",dataset[soda_ppu],">0",dataset[soda_units_sold],">0"),"No rows") -> 178699.89 | F40: =((E40-C40)/AVERAGE(C40,E40))/((D40-B40)/AVERAGE(B40,D40)) -> -0.43825104 | G40: Midpoint estimate suggests relatively inelastic demand; average units declined by less than the proportional increase in price.
A41: Medium | B41: =IFERROR(AVERAGEIFS(dataset[soda_ppu],dataset[zip_inc_tier],"Med",dataset[year_month],">=202201",dataset[year_month],"<=202212",dataset[soda_ppu],">0",dataset[soda_units_sold],">0"),"No rows") -> 0.69925278 | C41: =IFERROR(AVERAGEIFS(dataset[soda_units_sold],dataset[zip_inc_tier],"Med",dataset[year_month],">=202201",dataset[year_month],"<=202212",dataset[soda_ppu],">0",dataset[soda_units_sold],">0"),"No rows") -> 216231.04 | D41: =IFERROR(AVERAGEIFS(dataset[soda_ppu],dataset[zip_inc_tier],"Med",dataset[year_month],">=202401",dataset[year_month],"<=202412",dataset[soda_ppu],">0",dataset[soda_units_sold],">0"),"No rows") -> 0.75211415 | E41: =IFERROR(AVERAGEIFS(dataset[soda_units_sold],dataset[zip_inc_tier],"Med",dataset[year_month],">=202401",dataset[year_month],"<=202412",dataset[soda_ppu],">0",dataset[soda_units_sold],">0"),"No rows") -> 207636.96 | F41: =((E41-C41)/AVERAGE(C41,E41))/((D41-B41)/AVERAGE(B41,D41)) -> -0.55668267
A42: Low | B42: =IFERROR(AVERAGEIFS(dataset[soda_ppu],dataset[zip_inc_tier],"Low",dataset[year_month],">=202201",dataset[year_month],"<=202212",dataset[soda_ppu],">0",dataset[soda_units_sold],">0"),"No rows") -> 0.70662167 | C42: =IFERROR(AVERAGEIFS(dataset[soda_units_sold],dataset[zip_inc_tier],A42,dataset[year_month],">=202201",dataset[year_month],"<=202212",dataset[soda_ppu],">0",dataset[soda_units_sold],">0"),"No rows") -> 199425.65 | D42: =IFERROR(AVERAGEIFS(dataset[soda_ppu],dataset[zip_inc_tier],A42,dataset[year_month],">=202401",dataset[year_month],"<=202412",dataset[soda_ppu],">0",dataset[soda_units_sold],">0"),"No rows") -> 0.76279667 | E42: =IFERROR(AVERAGEIFS(dataset[soda_units_sold],dataset[zip_inc_tier],A42,dataset[year_month],">=202401",dataset[year_month],"<=202412",dataset[soda_ppu],">0",dataset[soda_units_sold],">0"),"No rows") -> 187032.03 | F42: =((E42-C42)/AVERAGE(C42,E42))/((D42-B42)/AVERAGE(B42,D42)) -> -0.83887738
A43: Midpoint elasticity was included as sensitivity check against the main constant elasticity. This midpoint estimate only compares average 2022 and 2024 price and quantity levels as such:
...

Sheet Revenue and Consumption
A1: This worksheet estimates the 2025 Virginia soda tax revenue and expected change in soda consumption under the proposed 5% ad valorem tax. This estimate uses 2024 Virginia soda sales and units as the baseline, scaling the Virginia sample of 33 to 1,000 stores as per the assignment. This will apply the full-sample income-tier constant elasticity estimates from the elasticity worksheet. Pass-through scenarios show how results change if 50%, 75%, or 100% of the tax is reflected in consumer prices.
A2: 100% Pass-Through Scenario
A3: state | B3: VA
A4: Income | B4: 2024
B6: VA Sample Store Count | C6: 2024 Soda Units | D6: 2024 Soda Sales | E6: Scale Factor | F6: Scaled Units | G6: Scaled Soda Sales | H6: Elasticity | I6: Tax Rate | J6: Est. % Change of Units (log-log proiection) | K6: Post-Tax Units | L6: Unit Change | M6: Sales after Demand Shift | N6: Est. Tax Revenue | O6: Notes
A7: High | B7: 11 | C7: 23124174 | D7: 17472271 | E7: 1000 / 33 = 30.30 | F7: =1000/33*GETPIVOTDATA("[Measures].[Sum of soda_units_sold]",$A$6,"[DimZip].[zip_inc_tier]","[DimZip].[zip_inc_tier].&[High]") -> 7.0073255e+08 | G7: =1000/33*GETPIVOTDATA("[Measures].[Sum of soda_sales]",$A$6,"[DimZip].[zip_inc_tier]","[DimZip].[zip_inc_tier].&[High]") -> 5.2946275e+08 | H7: =Elasticity!G7 -> -0.71035913 | I7: 0.05 | J7: =(1+I7)^H7-1 -> -0.03406481 | K7: =F7*(1+J7) -> 6.7686222e+08 | L7: =K7-F7 -> -23870321 | M7: =G7/F7*K7 -> 5.114267e+08 | N7: =M7*0.05 -> 25571335 | O7: Using VA-only High income tier elasticity produced an elastic (0.51) estimate, but this was only flagged as anomalous and not used for estimations.
A8: Medium | B8: 21 | C8: 51721008 | D8: 38908750 | E8: 1000 / 33 = 30.30 | F8: =1000/33*GETPIVOTDATA("[Measures].[Sum of soda_units_sold]",$A$6,"[DimZip].[zip_inc_tier]","[DimZip].[zip_inc_tier].&[Med]") -> 1.5673033e+09 | G8: =1000/33*GETPIVOTDATA("[Measures].[Sum of soda_sales]",$A$6,"[DimZip].[zip_inc_tier]","[DimZip].[zip_inc_tier].&[Med]") -> 1.179053e+09 | H8: =Elasticity!G8 -> -0.92885328 | I8: 0.05 | J8: =(1+I8)^H8-1 -> -0.044307341 | K8: =F8*(1+J8) -> 1.4978602e+09 | L8: =K8-F8 -> -69443041 | M8: =G8/F8*K8 -> 1.1268123e+09 | N8: =M8*0.05 -> 56340617
A9: Low | B9: 1 | C9: 1988027 | D9: 1512895.2 | E9: 1000 / 33 = 30.30 | F9: =1000/33*GETPIVOTDATA("[Measures].[Sum of soda_units_sold]",$A$6,"[DimZip].[zip_inc_tier]","[DimZip].[zip_inc_tier].&[Low]") -> 60243242 | G9: =1000/33*GETPIVOTDATA("[Measures].[Sum of soda_sales]",$A$6,"[DimZip].[zip_inc_tier]","[DimZip].[zip_inc_tier].&[Low]") -> 45845310 | H9: =Elasticity!G9 -> -1.9421318 | I9: 0.05 | J9: =(1+I9)^H9-1 -> -0.090405995 | K9: =F9*(1+J9) -> 54796892 | L9: =K9-F9 -> -5446350.3 | M9: =G9/F9*K9 -> 41700619 | N9: =M9*0.05 -> 2085031 | O9: Only one VA Low income store was observed, so the upscaled estimate should be treated with caution.
A10: Total | B10: 33 | C10: 76833209 | D10: 57893916 | E10: 1000 / 33 = 30.30 | F10: =1000/33*GETPIVOTDATA("[Measures].[Sum of soda_units_sold]",$A$6) -> 2.3282791e+09 | G10: =1000/33*GETPIVOTDATA("[Measures].[Sum of soda_sales]",$A$6) -> 1.7543611e+09 | H10: =Elasticity!G6 -> -0.97684053 | I10: 0.05 | J10: =(1+I10)^H10-1 -> -0.046542293 | K10: =SUM(K7:K9) -> 2.2295193e+09 | L10: =SUM(L7:L9) -> -98759712 | M10: =SUM(M7:M9) -> 1.6799397e+09 | N10: =SUM(N7:N9) -> 83996983
A11: Notes: Estimated demand response is based on elasticity and the assumed price increase. Tier-level estimates should be treated with caution as sample sizes differ, with the total row being our preferred estimates for revenue and demand effects.
A13: Pass-through sensitivity summary
A14: Pass-through | B14: Consumer Price Increase | C14: Post-Tax Units | D14: Unit Change | E14: % Unit Change | F14: Sales after Demand Shift | G14: Est. Tax Revenue
A15: 1 | B15: =0.05*A15 -> 0.05 | C15: =SUM(F7*(1+(1+B15)^H7-1),F8*(1+(1+B15)^H8-1),F9*(1+(1+B15)^H9-1)) -> 2.2295193e+09 | D15: =C15-F$10 -> -98759712 | E15: =(1+B15)^H10-1 -> -0.046542293 | F15: =SUM($G$7*(1+(1+B15)^$H$7-1),$G$8*(1+(1+B15)^$H$8-1),$G$9*(1+(1+B15)^$H$9-1)) -> 1.6799397e+09 | G15: =F15*0.05 -> 83996983
A16: 0.75 | B16: =0.05*A16 -> 0.0375 | C16: =SUM(F7*(1+(1+B16)^H7-1),F8*(1+(1+B16)^H8-1),F9*(1+(1+B16)^H9-1)) -> 2.2533471e+09 | D16: =C16-F$10 -> -74931930 | E16: =D16/F$10 -> -0.032183397 | F16: =SUM($G$7*(1+(1+B16)^$H$7-1),$G$8*(1+(1+B16)^$H$8-1),$G$9*(1+(1+B16)^$H$9-1)) -> 1.6978952e+09 | G16: =F16*0.05 -> 84894760
A17: 0.5 | B17: =0.05*A17 -> 0.025 | C17: =SUM(F7*(1+(1+B17)^H7-1),F8*(1+(1+B17)^H8-1),F9*(1+(1+B17)^H9-1)) -> 2.2777358e+09 | D17: =C17-F$10 -> -50543247 | E17: =D17/F$10 -> -0.021708415 | F17: =SUM($G$7*(1+(1+B17)^$H$7-1),$G$8*(1+(1+B17)^$H$8-1),$G$9*(1+(1+B17)^$H$9-1)) -> 1.7162735e+09 | G17: =F17*0.05 -> 85813675
A18: Total
A19: Notes: Consistent trend of lower pass-through produces higher estimated tax revenue, as the smaller consumer price increase leads to a smaller reduction in quantity demanded and thus a larger taxable sales base.
A22: Maryland Raw Soda Sales by Income Tier and Year
A23: state | B23: MD
A24: year_month | B24: All
B27: 2022 | F27: 2023 | J27: 2024
A28: Income Tier | B28: Store Count | C28: Avg Soda PPU | D28: Soda Units | E28: Soda Sales | F28: Store Count | G28: Avg Soda PPU | H28: Soda Units | I28: Soda Sales | J28: Store Count | K28: Avg Soda PPU | L28: Soda Units | M28: Soda Sales
A29: High | B29: 7 | C29: 0.71396548 | D29: 14882697 | E29: 10597280 | F29: 7 | G29: 0.734125 | H29: 14743133 | I29: 10779559 | J29: 7 | K29: 0.77092857 | L29: 14355280 | M29: 11043593
A30: Med | B30: 8 | C30: 0.69946146 | D30: 20429023 | E30: 14276206 | F30: 8 | G30: 0.72212188 | H30: 20090519 | I30: 14491121 | J30: 8 | K30: 0.75377917 | L30: 19608249 | M30: 14766446
A31: Grand Total | B31: 15 | C31: 0.70623 | D31: 35311720 | E31: 24873486 | F31: 15 | G31: 0.72772333 | H31: 34833652 | I31: 25270680 | J31: 15 | K31: 0.76178222 | L31: 33963529 | M31: 25810039
A33: North Carolina Raw Soda Sales by Income Tier and Year
A34: state | B34: NC
A35: year_month | B35: All
B38: 2022 | F38: 2023 | J38: 2024
A39: Income Tier | B39: Store Count | C39: Avg Soda PPU | D39: Soda Units | E39: Soda Sales | F39: Store Count | G39: Avg Soda PPU | H39: Soda Units | I39: Soda Sales | J39: Store Count | K39: Avg Soda PPU | L39: Soda Units | M39: Soda Sales
A40: Med | B40: 14 | C40: 0.71668095 | D40: 35621041 | E40: 25507289 | F40: 14 | G40: 0.75000357 | H40: 34204703 | I40: 25619798 | J40: 14 | K40: 0.79666607 | L40: 32746694 | M40: 26056467
A41: Low | B41: 2 | C41: 0.71374167 | D41: 4941584 | E41: 3518580.5 | F41: 2 | G41: 0.74614167 | H41: 4675391 | I41: 3471846.4 | J41: 2 | K41: 0.79495833 | L41: 4313546 | M41: 3422024.6
A42: No Data | B42: 3 | C42: 0.69621389 | D42: 7807255 | E42: 5429283.4 | F42: 3 | G42: 0.72691389 | H42: 7566403 | I42: 5492162.2 | J42: 3 | K42: 0.77713889 | L42: 7271937 | M42: 5642889.3
A43: Grand Total | B43: 19 | C43: 0.71313991 | D43: 48369880 | E43: 34455153 | F43: 19 | G43: 0.74595132 | H43: 46446497 | I43: 34583807 | J43: 19 | K43: 0.79340307 | L43: 44332177 | M43: 35121381
A45: Georgia Raw Soda Sales by Income Tier and Year
A46: state | B46: GA
A47: year_month | B47: All
B50: 2022 | F50: 2023 | J50: 2024
A51: Income Tier | B51: Store Count | C51: Avg Soda PPU | D51: Soda Units | E51: Soda Sales | F51: Store Count | G51: Avg Soda PPU | H51: Soda Units | I51: Soda Sales | J51: Store Count | K51: Avg Soda PPU | L51: Soda Units | M51: Soda Sales
A52: High | B52: 3 | C52: 0.65757222 | D52: 7432441 | E52: 4885861.3 | F52: 3 | G52: 0.67552778 | H52: 7319399 | I52: 4937740.8 | J52: 3 | K52: 0.69765556 | L52: 7238569 | M52: 5048473.9
...

Sheet Pivot
A1: Row Labels | B1: Sum of soda_sales | D1: Row Labels | E1: Sum of soda_sales | G1: Row Labels | H1: Sum of total_sales | I1: Sum of soda_sales
A2: 202201 | B2: 9824079.7 | D2: High | E2: 1.0906948e+08 | G2: DC | H2: 1.9974161e+08 | I2: 10616441
A3: 202202 | B3: 11132229 | D3: Low | E3: 25422407 | G3: GA | H3: 1.6276913e+09 | I3: 99053698
A4: 202203 | B4: 13102487 | D4: Med | E4: 3.470828e+08 | G4: MD | H4: 1.6628749e+09 | I4: 75954205
A5: 202204 | B5: 15255726 | D5: No Data | E5: 48048820 | G5: NC | H5: 1.6442658e+09 | I5: 1.0416034e+08
A6: 202205 | B6: 16742029 | D6: Grand Total | E6: 5.2962351e+08 | G6: VA | H6: 3.3024633e+09 | I6: 1.7050606e+08
A7: 202206 | B7: 17459533 | G7: WV | H7: 1.1245847e+09 | I7: 69332765
A8: 202207 | B8: 18006092 | G8: Grand Total | H8: 9.5616216e+09 | I8: 5.2962351e+08
A9: 202208 | B9: 15799476
A10: 202209 | B10: 15071250
A11: 202210 | B11: 14509826
A12: 202211 | B12: 13740015
A13: 202212 | B13: 13338841
A14: 202301 | B14: 9920396.6
A15: 202302 | B15: 11278475
A16: 202303 | B16: 13227993
A17: 202304 | B17: 15452669
A18: 202305 | B18: 17000119
A19: 202306 | B19: 17621038
A20: 202307 | B20: 18174788
... A37: 202412 | B37: 13840959
A38: Grand Total | B38: 5.2962351e+08

Sheet Visuals
A1: Summary Statistics | F1: obs: 3600
A2: Variable | B2: Mean | C2: Std.Dev. | D2: Min | E2: Median | F2: Max
A3: ='[1]Flat Data'!C1 -> total_sales | B3: =AVERAGE('[1]Flat Data'!C:C) -> 2656006 | C3: =_xlfn.STDEV.S('[1]Flat Data'!C:C) -> 660219.08 | D3: =MIN('[1]Flat Data'!C:C) -> 1286241 | E3: =MEDIAN('[1]Flat Data'!C:C) -> 2531489.1 | F3: =MAX('[1]Flat Data'!C:C) -> 5934473.6
A4: ='[1]Flat Data'!D1 -> soda_ppu | B4: =AVERAGE('[1]Flat Data'!D:D) -> 0.72502307 | C4: =_xlfn.STDEV.S('[1]Flat Data'!D:D) -> 0.041324884 | D4: =MIN('[1]Flat Data'!D:D) -> 0.60061552 | E4: =MEDIAN('[1]Flat Data'!D:D) -> 0.7235069 | F4: =MAX('[1]Flat Data'!D:D) -> 0.8625723
A5: ='[1]Flat Data'!E1 -> soda_units_sold | B5: =AVERAGE('[1]Flat Data'!E:E) -> 203580.39 | C5: =_xlfn.STDEV.S('[1]Flat Data'!E:E) -> 40947.526 | D5: =MIN('[1]Flat Data'!E:E) -> 69424 | E5: =MEDIAN('[1]Flat Data'!E:E) -> 205126.5 | F5: =MAX('[1]Flat Data'!E:E) -> 328920
A6: ='[1]Flat Data'!F1 -> soda_sales | B6: =AVERAGE('[1]Flat Data'!F:F) -> 147117.64 | C6: =_xlfn.STDEV.S('[1]Flat Data'!F:F) -> 28176.006 | D6: =MIN('[1]Flat Data'!F:F) -> 48509.86 | E6: =MEDIAN('[1]Flat Data'!F:F) -> 149106.27 | F6: =MAX('[1]Flat Data'!F:F) -> 211795.79
A7: ='[1]Flat Data'!G1 -> soda_sales_shares | B7: =AVERAGE('[1]Flat Data'!G:G) -> 0.058517994 | C7: =_xlfn.STDEV.S('[1]Flat Data'!G:G) -> 0.01664612 | D7: =MIN('[1]Flat Data'!G:G) -> 0.011222857 | E7: =MEDIAN('[1]Flat Data'!G:G) -> 0.05832408 | F7: =MAX('[1]Flat Data'!G:G) -> 0.11159551
A8: ='[1]Flat Data'!K1 -> med_income_avg | B8: =AVERAGE('[1]Flat Data'!K:K) -> 70859.363 | C8: =_xlfn.STDEV.S('[1]Flat Data'!K:K) -> 36880.998 | D8: =MIN('[1]Flat Data'!K:K) -> 0 | E8: =MEDIAN('[1]Flat Data'!K:K) -> 69087.833 | F8: =MAX('[1]Flat Data'!K:K) -> 176011.67
A9: *Observation count is 3,600 store-month observations with 100 stores x 36 months.
A11: Income Tier | B11: Scope | C11: Store-Month Obs. | D11: Distinct Stores | E11: Avg Soda PPU | F11: Avg Monthly Soda Units | G11: Avg Soda Sales | H11: Avg Soda Sales Share
A12: High | B12: All
B13: VA
A14: Medium | B14: All
B15: VA
A16: Low | B16: All
B17: VA
A18: No Data | B18: All
B19: VA
A20: Total | B20: 3600 | C20: 100
A22: Income tier observations
A23: High | B23: Medium | C23: Low | D23: No Data
A24: =COUNTIF('[1]Flat Data'!J:J,"High") -> #VALUE! | B24: =COUNTIF('[1]Flat Data'!J:J,"Med") -> #VALUE! | C24: =COUNTIF('[1]Flat Data'!J:J,"Low") -> #VALUE! | D24: =COUNTIF('[1]Flat Data'!J:J,"No Data") -> #VALUE!
A26: State coverage (distinct stores)
A27: VA | B27: MD | C27: DC | D27: WV | E27: NC | F27: GA
A28: =COUNTIF('[1]Flat Data'!I:I,"VA")/36 -> #VALUE! | B28: =COUNTIF('[1]Flat Data'!I:I,"MD")/36 -> #VALUE! | C28: =COUNTIF('[1]Flat Data'!I:I,"DC")/36 -> #VALUE! | D28: =COUNTIF('[1]Flat Data'!I:I,"WV")/36 -> #VALUE! | E28: =COUNTIF('[1]Flat Data'!I:I,"NC")/36 -> #VALUE! | F28: =COUNTIF('[1]Flat Data'!I:I,"GA")/36 -> #VALUE!

Sheet dataset
A1: year_month | B1: store_id | C1: total_sales | D1: soda_ppu | E1: soda_units_sold | F1: soda_sales | G1: zip | H1: state | I1: zip_med_inc_avg | J1: zip_inc_tier | K1: implied_soda_ppu | L1: check_soda_ppu | M1: soda_sales_share | N1: ln_soda_units | O1: ln_soda_sales | P1: ln_soda_ppu | Q1: is_VA
A2: 202201 | B2: 2 | C2: 2267236.9 | D2: 0.7071 | E2: 142774 | F2: 100953.27 | G2: 20024 | H2: DC | I2: =HLOOKUP(G2,zip_tiers!$A$1:$EON$2,2,FALSE) -> 102576 | J2: =IF(I2="","No Data",IF(I2>=100000,"High",IF(I2>=40000,"Med","Low"))) -> High | K2: =dataset[[#This Row],[soda_sales]]/dataset[[#This Row],[soda_units_sold]] -> 0.70708444 | L2: =dataset[[#This Row],[implied_soda_ppu]]-dataset[[#This Row],[soda_ppu]] -> -1.5556754e-05 | M2: =dataset[[#This Row],[soda_sales]]/dataset[[#This Row],[total_sales]] -> 0.044527007 | N2: =LN(dataset[[#This Row],[soda_units_sold]]) -> 11.869018 | O2: =LN(dataset[[#This Row],[soda_sales]]) -> 11.522413 | P2: =LN(dataset[[#This Row],[soda_ppu]]) -> -0.34658318 | Q2: =IF(dataset[[#This Row],[state]]="VA",1,0) -> 0
A3: 202202 | B3: 2 | C3: 2508276.2 | D3: 0.6961 | E3: 159898 | F3: 111309.18 | G3: 20024 | H3: DC | I3: =HLOOKUP(G3,zip_tiers!$A$1:$EON$2,2,FALSE) -> 102576 | J3: =IF(I3="","No Data",IF(I3>=100000,"High",IF(I3>=40000,"Med","Low"))) -> High | K3: =dataset[[#This Row],[soda_sales]]/dataset[[#This Row],[soda_units_sold]] -> 0.69612618 | L3: =dataset[[#This Row],[implied_soda_ppu]]-dataset[[#This Row],[soda_ppu]] -> 2.6184192e-05 | M3: =dataset[[#This Row],[soda_sales]]/dataset[[#This Row],[total_sales]] -> 0.044376765 | N3: =LN(dataset[[#This Row],[soda_units_sold]]) -> 11.982291 | O3: =LN(dataset[[#This Row],[soda_sales]]) -> 11.620067 | P3: =LN(dataset[[#This Row],[soda_ppu]]) -> -0.36226195 | Q3: =IF(dataset[[#This Row],[state]]="VA",1,0) -> 0
A4: 202203 | B4: 2 | C4: 2817658.1 | D4: 0.7273 | E4: 185067 | F4: 134594.64 | G4: 20024 | H4: DC | I4: =HLOOKUP(G4,zip_tiers!$A$1:$EON$2,2,FALSE) -> 102576 | J4: =IF(I4="","No Data",IF(I4>=100000,"High",IF(I4>=40000,"Med","Low"))) -> High | K4: =dataset[[#This Row],[soda_sales]]/dataset[[#This Row],[soda_units_sold]] -> 0.7272752 | L4: =dataset[[#This Row],[implied_soda_ppu]]-dataset[[#This Row],[soda_ppu]] -> -2.4802369e-05 | M4: =dataset[[#This Row],[soda_sales]]/dataset[[#This Row],[total_sales]] -> 0.047768266 | N4: =LN(dataset[[#This Row],[soda_units_sold]]) -> 12.128473 | O4: =LN(dataset[[#This Row],[soda_sales]]) -> 11.810023 | P4: =LN(dataset[[#This Row],[soda_ppu]]) -> -0.31841623 | Q4: =IF(dataset[[#This Row],[state]]="VA",1,0) -> 0
A5: 202204 | B5: 2 | C5: 2944587.7 | D5: 0.737 | E5: 210840 | F5: 155395.96 | G5: 20024 | H5: DC | I5: =HLOOKUP(G5,zip_tiers!$A$1:$EON$2,2,FALSE) -> 102576 | J5: =IF(I5="","No Data",IF(I5>=100000,"High",IF(I5>=40000,"Med","Low"))) -> High | K5: =dataset[[#This Row],[soda_sales]]/dataset[[#This Row],[soda_units_sold]] -> 0.73703265 | L5: =dataset[[#This Row],[implied_soda_ppu]]-dataset[[#This Row],[soda_ppu]] -> 3.2645608e-05 | M5: =dataset[[#This Row],[soda_sales]]/dataset[[#This Row],[total_sales]] -> 0.052773419 | N5: =LN(dataset[[#This Row],[soda_units_sold]]) -> 12.258855 | O5: =LN(dataset[[#This Row],[soda_sales]]) -> 11.953732 | P5: =LN(dataset[[#This Row],[soda_ppu]]) -> -0.30516739 | Q5: =IF(dataset[[#This Row],[state]]="VA",1,0) -> 0
A6: 202205 | B6: 2 | C6: 3068859.8 | D6: 0.7225 | E6: 232179 | F6: 167743.05 | G6: 20024 | H6: DC | I6: =HLOOKUP(G6,zip_tiers!$A$1:$EON$2,2,FALSE) -> 102576 | J6: =IF(I6="","No Data",IF(I6>=100000,"High",IF(I6>=40000,"Med","Low"))) -> High | K6: =dataset[[#This Row],[soda_sales]]/dataset[[#This Row],[soda_units_sold]] -> 0.72247295 | L6: =dataset[[#This Row],[implied_soda_ppu]]-dataset[[#This Row],[soda_ppu]] -> -2.705025e-05 | M6: =dataset[[#This Row],[soda_sales]]/dataset[[#This Row],[total_sales]] -> 0.05465973 | N6: =LN(dataset[[#This Row],[soda_units_sold]]) -> 12.355264 | O6: =LN(dataset[[#This Row],[soda_sales]]) -> 12.030189 | P6: =LN(dataset[[#This Row],[soda_ppu]]) -> -0.32503786 | Q6: =IF(dataset[[#This Row],[state]]="VA",1,0) -> 0
A7: 202206 | B7: 2 | C7: 2997245.4 | D7: 0.694 | E7: 250867 | F7: 174091.2 | G7: 20024 | H7: DC | I7: =HLOOKUP(G7,zip_tiers!$A$1:$EON$2,2,FALSE) -> 102576 | J7: =IF(I7="","No Data",IF(I7>=100000,"High",IF(I7>=40000,"Med","Low"))) -> High | K7: =dataset[[#This Row],[soda_sales]]/dataset[[#This Row],[soda_units_sold]] -> 0.69395817 | L7: =dataset[[#This Row],[implied_soda_ppu]]-dataset[[#This Row],[soda_ppu]] -> -4.1834119e-05 | M7: =dataset[[#This Row],[soda_sales]]/dataset[[#This Row],[total_sales]] -> 0.058083734 | N7: =LN(dataset[[#This Row],[soda_units_sold]]) -> 12.432678 | O7: =LN(dataset[[#This Row],[soda_sales]]) -> 12.067335 | P7: =LN(dataset[[#This Row],[soda_ppu]]) -> -0.36528332 | Q7: =IF(dataset[[#This Row],[state]]="VA",1,0) -> 0
A8: 202207 | B8: 2 | C8: 2849718.7 | D8: 0.7117 | E8: 256267 | F8: 182384.29 | G8: 20024 | H8: DC | I8: =HLOOKUP(G8,zip_tiers!$A$1:$EON$2,2,FALSE) -> 102576 | J8: =IF(I8="","No Data",IF(I8>=100000,"High",IF(I8>=40000,"Med","Low"))) -> High | K8: =dataset[[#This Row],[soda_sales]]/dataset[[#This Row],[soda_units_sold]] -> 0.71169636 | L8: =dataset[[#This Row],[implied_soda_ppu]]-dataset[[#This Row],[soda_ppu]] -> -3.6434656e-06 | M8: =dataset[[#This Row],[soda_sales]]/dataset[[#This Row],[total_sales]] -> 0.064000804 | N8: =LN(dataset[[#This Row],[soda_units_sold]]) -> 12.453975 | O8: =LN(dataset[[#This Row],[soda_sales]]) -> 12.113871 | P8: =LN(dataset[[#This Row],[soda_ppu]]) -> -0.3400988 | Q8: =IF(dataset[[#This Row],[state]]="VA",1,0) -> 0
A9: 202208 | B9: 2 | C9: 2668677.8 | D9: 0.7081 | E9: 224536 | F9: 158994.89 | G9: 20024 | H9: DC | I9: =HLOOKUP(G9,zip_tiers!$A$1:$EON$2,2,FALSE) -> 102576 | J9: =IF(I9="","No Data",IF(I9>=100000,"High",IF(I9>=40000,"Med","Low"))) -> High | K9: =dataset[[#This Row],[soda_sales]]/dataset[[#This Row],[soda_units_sold]] -> 0.70810423 | L9: =dataset[[#This Row],[implied_soda_ppu]]-dataset[[#This Row],[soda_ppu]] -> 4.2287206e-06 | M9: =dataset[[#This Row],[soda_sales]]/dataset[[#This Row],[total_sales]] -> 0.059578153 | N9: =LN(dataset[[#This Row],[soda_units_sold]]) -> 12.321791 | O9: =LN(dataset[[#This Row],[soda_sales]]) -> 11.976627 | P9: =LN(dataset[[#This Row],[soda_ppu]]) -> -0.34516995 | Q9: =IF(dataset[[#This Row],[state]]="VA",1,0) -> 0
